Workbook

Sheet Recap
A1: Test | B1: Test Generation Time | C1: Mutation Testing Time | D1: Mutation Score
A2: AMM_100_0.01_no_pi | B2: 164.51787 | C2: ='AMM_100_0.01_no_pi'!$K$46*60 | D2: ='AMM_100_0.01_no_pi'!$J$46
A3: AMM_100_0.01_no_pi | B3: 86.569823 | C3: ='AMM_100_0.01_no_pi'!$K$46*60 | D3: ='AMM_100_0.01_no_pi'!$J$46
A4: AssetTransfer_5000_0.01_no_pi | B4: 37.260516 | C4: ='AssetTransfer_5000_0.01_no_pi'!$K$46*60 | D4: ='AssetTransfer_5000_0.01_no_pi'!$J$46
A5: BasicProvenance_10000_0.01_no_pi | B5: 337.37448 | C5: ='BasicProvenance_10000_0.01_no_pi'!$K$46*60 | D5: ='BasicProvenance_10000_0.01_no_pi'!$J$46
A6: Cm_5000_0.01_no_pi | B6: 576.93235 | C6: ='Cm_5000_0.01_no_pi'!$K$46*60 | D6: ='Cm_5000_0.01_no_pi'!$J$46
A7: DefectiveCounter_10000_0.01_no_pi | B7: 39.384301 | C7: ='DefectiveCounter_10000_0.01_no_pi'!$K$46*60 | D7: ='DefectiveCounter_10000_0.01_no_pi'!$J$46
A8: DefectiveCounter_10000_0.5_no_pi | B8: 47.820299 | C8: ='DefectiveCounter_10000_0.5_no_pi'!$K$46*60 | D8: ='DefectiveCounter_10000_0.5_no_pi'!$J$46
A9: FrequentFlyer_10000_0.01_no_pi | B9: 641.54854 | C9: ='FrequentFlyer_10000_0.01_no_pi'!$K$46*60 | D9: ='FrequentFlyer_10000_0.01_no_pi'!$J$46
A10: FrequentFlyer_10000_0.5_no_pi | B10: 319.38061 | C10: ='FrequentFlyer_10000_0.5_no_pi'!$K$46*60 | D10: ='FrequentFlyer_10000_0.5_no_pi'!$J$46
A11: HelloBlockchain_10000_0.01_no_pi | B11: 54.198546 | C11: ='HelloBlockchain_10000_0.01_no_pi'!$K$46*60 | D11: ='HelloBlockchain_10000_0.01_no_pi'!$J$46
A12: RefrigeratedTransport_10000_0.01_no_pi | B12: 119.49519 | C12: ='RefrigeratedTransport_10000_0.01_no_pi'!$K$46*60 | D12: ='RefrigeratedTransport_10000_0.01_no_pi'!$J$46
A13: Simplemarketplace_10000_0.01_no_pi | B13: 169.6555 | C13: ='Simplemarketplace_10000_0.01_no_pi'!$K$46*60 | D13: ='Simplemarketplace_10000_0.01_no_pi'!$J$46
A14: ThermostatOperation_10000_0.5_no_pi | B14: 337.63991 | C14: ='ThermostatOperation_10000_0.5_no_pi'!$K$46*60 | D14: ='ThermostatOperation_10000_0.5_no_pi'!$J$46
A15: Token1_10000_0.01_no_pi | B15: 740.3358 | C15: ='Token1_10000_0.01_no_pi'!$K$46*60 | D15: ='Token1_10000_0.01_no_pi'!$J$46
A16: WalletContract_10000_0.01_no_pi | B16: 165.893 | C16: ='WalletContract_10000_0.01_no_pi'!$K$46*60 | D16: ='WalletContract_10000_0.01_no_pi'!$J$46
A21: Test | B21: PI | C21: NO_PI
A22: AMM_100_0.01 | C22: ='AMM_100_0.01_no_pi'!$J$46
A23: AssetTransfer_5000_0.01 | C23: ='AssetTransfer_5000_0.01_no_pi'!$J$46
A24: BasicProvenance_10000_0.01 | C24: ='BasicProvenance_10000_0.01_no_pi'!$J$46
A25: Cm_5000_0.01 | C25: ='Cm_5000_0.01_no_pi'!$J$46
A26: DefectiveCounter_10000_0.01 | C26: ='DefectiveCounter_10000_0.01_no_pi'!$J$46
A27: DefectiveCounter_10000_0.5 | C27: ='DefectiveCounter_10000_0.5_no_pi'!$J$46
A28: FrequentFlyer_10000_0.01 | C28: ='FrequentFlyer_10000_0.01_no_pi'!$J$46
A29: FrequentFlyer_10000_0.5 | C29: ='FrequentFlyer_10000_0.5_no_pi'!$J$46
A30: HelloBlockchain_10000_0.01 | C30: ='HelloBlockchain_10000_0.01_no_pi'!$J$46
A31: RefrigeratedTransport_10000_0.01 | C31: ='RefrigeratedTransport_10000_0.01_no_pi'!$J$46
A32: Simplemarketplace_10000_0.01 | C32: ='Simplemarketplace_10000_0.01_no_pi'!$J$46
A33: ThermostatOperation_10000_0.5 | C33: ='ThermostatOperation_10000_0.5_no_pi'!$J$46
A34: Token1_10000_0.01 | C34: ='Token1_10000_0.01_no_pi'!$J$46
A35: WalletContract_10000_0.01 | C35: ='WalletContract_10000_0.01_no_pi'!$J$46

Sheet AMM_100_0.01_no_pi
A1: Operator | B1: Total | C1: Equivalent | D1: Redundant | E1: Valid | F1: Killed | G1: Live | H1: Timedout | I1: Stillborn | J1: Mutation Score | K1: Testing Time
A2: ACM | B2: 0 | C2: 0 | D2: 0 | E2: 0 | F2: 0 | G2: 0 | H2: 0 | I2: 0 | K2: 0
A3: AOR | B3: 0 | C3: 0 | D3: 0 | E3: 0 | F3: 0 | G3: 0 | H3: 0 | I3: 0 | K3: 0
A4: AVR | B4: 6 | C4: 0 | D4: 0 | E4: 6 | F4: 2 | G4: 4 | H4: 0 | I4: 0 | J4: 33.333333 | K4: 3.1179
A5: BCRD | B5: 0 | C5: 0 | D5: 0 | E5: 0 | F5: 0 | G5: 0 | H5: 0 | I5: 0 | K5: 0
A6: BLR | B6: 12 | C6: 0 | D6: 0 | E6: 12 | F6: 10 | G6: 2 | H6: 0 | I6: 0 | J6: 83.333333 | K6: 3.33595
A7: BOR | B7: 200 | C7: 0 | D7: 0 | E7: 200 | F7: 135 | G7: 65 | H7: 0 | I7: 0 | J7: 67.5 | K7: 78.567983
A8: CBD | B8: 0 | C8: 0 | D8: 0 | E8: 0 | F8: 0 | G8: 0 | H8: 0 | I8: 0 | K8: 0
A9: CCD | B9: 3 | C9: 0 | D9: 0 | E9: 3 | F9: 3 | G9: 0 | H9: 0 | I9: 0 | J9: 100 | K9: 0.59836667
A10: CSC | B10: 53 | C10: 0 | D10: 0 | E10: 53 | F10: 34 | G10: 19 | H10: 0 | I10: 0 | J10: 64.150943 | K10: 19.860367
A11: DLR | B11: 4 | C11: 0 | D11: 0 | E11: 0 | F11: 0 | G11: 0 | H11: 0 | I11: 4 | K11: 0
A12: DOD | B12: 0 | C12: 0 | D12: 0 | E12: 0 | F12: 0 | G12: 0 | H12: 0 | I12: 0 | K12: 0
A13: ECS | B13: 0 | C13: 0 | D13: 0 | E13: 0 | F13: 0 | G13: 0 | H13: 0 | I13: 0 | K13: 0
A14: EED | B14: 0 | C14: 0 | D14: 0 | E14: 0 | F14: 0 | G14: 0 | H14: 0 | I14: 0 | K14: 0
A15: EHC | B15: 45 | C15: 0 | D15: 0 | E15: 45 | F15: 18 | G15: 27 | H15: 0 | I15: 0 | J15: 40 | K15: 21.18145
A16: ER | B16: 15 | C16: 0 | D16: 0 | E16: 15 | F16: 9 | G16: 6 | H16: 0 | I16: 0 | J16: 60 | K16: 6.46305
A17: ETR | B17: 8 | C17: 0 | D17: 0 | E17: 0 | F17: 0 | G17: 0 | H17: 0 | I17: 8 | K17: 0
A18: FVR | B18: 15 | C18: 0 | D18: 0 | E18: 11 | F18: 10 | G18: 1 | H18: 0 | I18: 4 | J18: 90.909091 | K18: 2.6424
A19: GVR | B19: 0 | C19: 0 | D19: 0 | E19: 0 | F19: 0 | G19: 0 | H19: 0 | I19: 0 | K19: 0
A20: HLR | B20: 0 | C20: 0 | D20: 0 | E20: 0 | F20: 0 | G20: 0 | H20: 0 | I20: 0 | K20: 0
A21: ILR | B21: 35 | C21: 0 | D21: 0 | E21: 35 | F21: 20 | G21: 15 | H21: 0 | I21: 0 | J21: 57.142857 | K21: 15.570033
A22: ICM | B22: 0 | C22: 0 | D22: 0 | E22: 0 | F22: 0 | G22: 0 | H22: 0 | I22: 0 | K22: 0
A23: LSC | B23: 0 | C23: 0 | D23: 0 | E23: 0 | F23: 0 | G23: 0 | H23: 0 | I23: 0 | K23: 0
A24: PKD | B24: 0 | C24: 0 | D24: 0 | E24: 0 | F24: 0 | G24: 0 | H24: 0 | I24: 0 | K24: 0
A25: MCR | B25: 0 | C25: 0 | D25: 0 | E25: 0 | F25: 0 | G25: 0 | H25: 0 | I25: 0 | K25: 0
A26: MOC | B26: 0 | C26: 0 | D26: 0 | E26: 0 | F26: 0 | G26: 0 | H26: 0 | I26: 0 | K26: 0
A27: MOD | B27: 0 | C27: 0 | D27: 0 | E27: 0 | F27: 0 | G27: 0 | H27: 0 | I27: 0 | K27: 0
A28: MOI | B28: 1 | C28: 0 | D28: 0 | E28: 0 | F28: 0 | G28: 0 | H28: 0 | I28: 1 | K28: 0
A29: MOR | B29: 0 | C29: 0 | D29: 0 | E29: 0 | F29: 0 | G29: 0 | H29: 0 | I29: 0 | K29: 0
A30: OLFD | B30: 0 | C30: 0 | D30: 0 | E30: 0 | F30: 0 | G30: 0 | H30: 0 | I30: 0 | K30: 0
A31: OMD | B31: 0 | C31: 0 | D31: 0 | E31: 0 | F31: 0 | G31: 0 | H31: 0 | I31: 0 | K31: 0
A32: ORFD | B32: 0 | C32: 0 | D32: 0 | E32: 0 | F32: 0 | G32: 0 | H32: 0 | I32: 0 | K32: 0
A33: RSD | B33: 1 | C33: 0 | D33: 0 | E33: 1 | F33: 1 | G33: 0 | H33: 0 | I33: 0 | J33: 100 | K33: 0.42186667
A34: RVS | B34: 0 | C34: 0 | D34: 0 | E34: 0 | F34: 0 | G34: 0 | H34: 0 | I34: 0 | K34: 0
A35: SCEC | B35: 0 | C35: 0 | D35: 0 | E35: 0 | F35: 0 | G35: 0 | H35: 0 | I35: 0 | K35: 0
A36: SFI | B36: 0 | C36: 0 | D36: 0 | E36: 0 | F36: 0 | G36: 0 | H36: 0 | I36: 0 | K36: 0
A37: SFD | B37: 0 | C37: 0 | D37: 0 | E37: 0 | F37: 0 | G37: 0 | H37: 0 | I37: 0 | K37: 0
A38: SFR | B38: 0 | C38: 0 | D38: 0 | E38: 0 | F38: 0 | G38: 0 | H38: 0 | I38: 0 | K38: 0
A39: SKD | B39: 0 | C39: 0 | D39: 0 | E39: 0 | F39: 0 | G39: 0 | H39: 0 | I39: 0 | K39: 0
A40: SKI | B40: 0 | C40: 0 | D40: 0 | E40: 0 | F40: 0 | G40: 0 | H40: 0 | I40: 0 | K40: 0
...

Sheet AssetTransfer_5000_0.01_no_pi
A1: Operator | B1: Total | C1: Equivalent | D1: Redundant | E1: Valid | F1: Killed | G1: Live | H1: Timedout | I1: Stillborn | J1: Mutation Score | K1: Testing Time
A2: ACM | B2: 0 | C2: 0 | D2: 0 | E2: 0 | F2: 0 | G2: 0 | H2: 0 | I2: 0 | K2: 0
A3: AOR | B3: 0 | C3: 0 | D3: 0 | E3: 0 | F3: 0 | G3: 0 | H3: 0 | I3: 0 | K3: 0
A4: AVR | B4: 0 | C4: 0 | D4: 0 | E4: 0 | F4: 0 | G4: 0 | H4: 0 | I4: 0 | K4: 0
A5: BCRD | B5: 0 | C5: 0 | D5: 0 | E5: 0 | F5: 0 | G5: 0 | H5: 0 | I5: 0 | K5: 0
A6: BLR | B6: 43 | C6: 0 | D6: 0 | E6: 43 | F6: 43 | G6: 0 | H6: 0 | I6: 0 | J6: 100 | K6: 12.500683
A7: BOR | B7: 94 | C7: 0 | D7: 0 | E7: 94 | F7: 71 | G7: 23 | H7: 0 | I7: 0 | J7: 75.531915 | K7: 45.22265
A8: CBD | B8: 0 | C8: 0 | D8: 0 | E8: 0 | F8: 0 | G8: 0 | H8: 0 | I8: 0 | K8: 0
A9: CCD | B9: 1 | C9: 0 | D9: 0 | E9: 1 | F9: 1 | G9: 0 | H9: 0 | I9: 0 | J9: 100 | K9: 0.20385
A10: CSC | B10: 75 | C10: 0 | D10: 0 | E10: 75 | F10: 67 | G10: 8 | H10: 0 | I10: 0 | J10: 89.333333 | K10: 25.169967
A11: DLR | B11: 1 | C11: 0 | D11: 0 | E11: 0 | F11: 0 | G11: 0 | H11: 0 | I11: 1 | K11: 0
A12: DOD | B12: 0 | C12: 0 | D12: 0 | E12: 0 | F12: 0 | G12: 0 | H12: 0 | I12: 0 | K12: 0
A13: ECS | B13: 0 | C13: 0 | D13: 0 | E13: 0 | F13: 0 | G13: 0 | H13: 0 | I13: 0 | K13: 0
A14: EED | B14: 0 | C14: 0 | D14: 0 | E14: 0 | F14: 0 | G14: 0 | H14: 0 | I14: 0 | K14: 0
A15: EHC | B15: 29 | C15: 0 | D15: 0 | E15: 29 | F15: 8 | G15: 21 | H15: 0 | I15: 0 | J15: 27.586207 | K15: 22.9316
A16: ER | B16: 65 | C16: 0 | D16: 0 | E16: 65 | F16: 53 | G16: 12 | H16: 0 | I16: 0 | J16: 81.538462 | K16: 27.45345
A17: ETR | B17: 0 | C17: 0 | D17: 0 | E17: 0 | F17: 0 | G17: 0 | H17: 0 | I17: 0 | K17: 0
A18: FVR | B18: 10 | C18: 0 | D18: 0 | E18: 10 | F18: 10 | G18: 0 | H18: 0 | I18: 0 | J18: 100 | K18: 2.0643833
A19: GVR | B19: 0 | C19: 0 | D19: 0 | E19: 0 | F19: 0 | G19: 0 | H19: 0 | I19: 0 | K19: 0
A20: HLR | B20: 0 | C20: 0 | D20: 0 | E20: 0 | F20: 0 | G20: 0 | H20: 0 | I20: 0 | K20: 0
A21: ILR | B21: 49 | C21: 0 | D21: 0 | E21: 49 | F21: 45 | G21: 4 | H21: 0 | I21: 0 | J21: 91.836735 | K21: 18.963617
A22: ICM | B22: 0 | C22: 0 | D22: 0 | E22: 0 | F22: 0 | G22: 0 | H22: 0 | I22: 0 | K22: 0
A23: LSC | B23: 0 | C23: 0 | D23: 0 | E23: 0 | F23: 0 | G23: 0 | H23: 0 | I23: 0 | K23: 0
A24: PKD | B24: 0 | C24: 0 | D24: 0 | E24: 0 | F24: 0 | G24: 0 | H24: 0 | I24: 0 | K24: 0
A25: MCR | B25: 0 | C25: 0 | D25: 0 | E25: 0 | F25: 0 | G25: 0 | H25: 0 | I25: 0 | K25: 0
A26: MOC | B26: 0 | C26: 0 | D26: 0 | E26: 0 | F26: 0 | G26: 0 | H26: 0 | I26: 0 | K26: 0
A27: MOD | B27: 0 | C27: 0 | D27: 0 | E27: 0 | F27: 0 | G27: 0 | H27: 0 | I27: 0 | K27: 0
A28: MOI | B28: 0 | C28: 0 | D28: 0 | E28: 0 | F28: 0 | G28: 0 | H28: 0 | I28: 0 | K28: 0
A29: MOR | B29: 0 | C29: 0 | D29: 0 | E29: 0 | F29: 0 | G29: 0 | H29: 0 | I29: 0 | K29: 0
A30: OLFD | B30: 0 | C30: 0 | D30: 0 | E30: 0 | F30: 0 | G30: 0 | H30: 0 | I30: 0 | K30: 0
A31: OMD | B31: 0 | C31: 0 | D31: 0 | E31: 0 | F31: 0 | G31: 0 | H31: 0 | I31: 0 | K31: 0
A32: ORFD | B32: 0 | C32: 0 | D32: 0 | E32: 0 | F32: 0 | G32: 0 | H32: 0 | I32: 0 | K32: 0
A33: RSD | B33: 0 | C33: 0 | D33: 0 | E33: 0 | F33: 0 | G33: 0 | H33: 0 | I33: 0 | K33: 0
... A44: VUR | B44: 0 | C44: 0 | D44: 0 | E44: 0 | F44: 0 | G44: 0 | H44: 0 | I44: 0 | K44: 0
A45: VVR | B45: 4 | C45: 0 | D45: 0 | E45: 4 | F45: 3 | G45: 1 | H45: 0 | I45: 0 | J45: 75 | K45: 1.75545
A46: All | B46: =SUM(B2:B45) | C46: =SUM(C2:C45) | D46: =SUM(D2:D45) | E46: =SUM(E2:E45) | F46: =SUM(F2:F45) | G46: =SUM(G2:G45) | H46: =SUM(H2:H45) | I46: =SUM(I2:I45) | J46: =(F46+I46)/B46*100 | K46: =SUM(K2:K45)

Sheet BasicProvenance_10000_0.01_no_pi
A1: Operator | B1: Total | C1: Equivalent | D1: Redundant | E1: Valid | F1: Killed | G1: Live | H1: Timedout | I1: Stillborn | J1: Mutation Score | K1: Testing Time
A2: ACM | B2: 0 | C2: 0 | D2: 0 | E2: 0 | F2: 0 | G2: 0 | H2: 0 | I2: 0 | K2: 0
A3: AOR | B3: 0 | C3: 0 | D3: 0 | E3: 0 | F3: 0 | G3: 0 | H3: 0 | I3: 0 | K3: 0
A4: AVR | B4: 0 | C4: 0 | D4: 0 | E4: 0 | F4: 0 | G4: 0 | H4: 0 | I4: 0 | K4: 0
A5: BCRD | B5: 0 | C5: 0 | D5: 0 | E5: 0 | F5: 0 | G5: 0 | H5: 0 | I5: 0 | K5: 0
A6: BLR | B6: 8 | C6: 0 | D6: 0 | E6: 8 | F6: 8 | G6: 0 | H6: 0 | I6: 0 | J6: 100 | K6: 1.7444
A7: BOR | B7: 9 | C7: 0 | D7: 0 | E7: 9 | F7: 9 | G7: 0 | H7: 0 | I7: 0 | J7: 100 | K7: 1.99395
A8: CBD | B8: 0 | C8: 0 | D8: 0 | E8: 0 | F8: 0 | G8: 0 | H8: 0 | I8: 0 | K8: 0
A9: CCD | B9: 1 | C9: 0 | D9: 0 | E9: 1 | F9: 1 | G9: 0 | H9: 0 | I9: 0 | J9: 100 | K9: 0.2102
A10: CSC | B10: 11 | C10: 0 | D10: 0 | E10: 11 | F10: 9 | G10: 2 | H10: 0 | I10: 0 | J10: 81.818182 | K10: 7.2181167
A11: DLR | B11: 0 | C11: 0 | D11: 0 | E11: 0 | F11: 0 | G11: 0 | H11: 0 | I11: 0 | K11: 0
A12: DOD | B12: 0 | C12: 0 | D12: 0 | E12: 0 | F12: 0 | G12: 0 | H12: 0 | I12: 0 | K12: 0
A13: ECS | B13: 0 | C13: 0 | D13: 0 | E13: 0 | F13: 0 | G13: 0 | H13: 0 | I13: 0 | K13: 0
A14: EED | B14: 0 | C14: 0 | D14: 0 | E14: 0 | F14: 0 | G14: 0 | H14: 0 | I14: 0 | K14: 0
A15: EHC | B15: 9 | C15: 0 | D15: 0 | E15: 9 | F15: 3 | G15: 6 | H15: 0 | I15: 0 | J15: 33.333333 | K15: 14.499533
A16: ER | B16: 9 | C16: 0 | D16: 0 | E16: 9 | F16: 6 | G16: 3 | H16: 0 | I16: 0 | J16: 66.666667 | K16: 8.14755
A17: ETR | B17: 0 | C17: 0 | D17: 0 | E17: 0 | F17: 0 | G17: 0 | H17: 0 | I17: 0 | K17: 0
A18: FVR | B18: 2 | C18: 0 | D18: 0 | E18: 2 | F18: 2 | G18: 0 | H18: 0 | I18: 0 | J18: 100 | K18: 0.43055
A19: GVR | B19: 0 | C19: 0 | D19: 0 | E19: 0 | F19: 0 | G19: 0 | H19: 0 | I19: 0 | K19: 0
A20: HLR | B20: 0 | C20: 0 | D20: 0 | E20: 0 | F20: 0 | G20: 0 | H20: 0 | I20: 0 | K20: 0
A21: ILR | B21: 6 | C21: 0 | D21: 0 | E21: 6 | F21: 5 | G21: 1 | H21: 0 | I21: 0 | J21: 83.333333 | K21: 3.2732833
A22: ICM | B22: 0 | C22: 0 | D22: 0 | E22: 0 | F22: 0 | G22: 0 | H22: 0 | I22: 0 | K22: 0
A23: LSC | B23: 0 | C23: 0 | D23: 0 | E23: 0 | F23: 0 | G23: 0 | H23: 0 | I23: 0 | K23: 0
A24: PKD | B24: 0 | C24: 0 | D24: 0 | E24: 0 | F24: 0 | G24: 0 | H24: 0 | I24: 0 | K24: 0
A25: MCR | B25: 0 | C25: 0 | D25: 0 | E25: 0 | F25: 0 | G25: 0 | H25: 0 | I25: 0 | K25: 0
A26: MOC | B26: 0 | C26: 0 | D26: 0 | E26: 0 | F26: 0 | G26: 0 | H26: 0 | I26: 0 | K26: 0
A27: MOD | B27: 0 | C27: 0 | D27: 0 | E27: 0 | F27: 0 | G27: 0 | H27: 0 | I27: 0 | K27: 0
A28: MOI | B28: 0 | C28: 0 | D28: 0 | E28: 0 | F28: 0 | G28: 0 | H28: 0 | I28: 0 | K28: 0
A29: MOR | B29: 0 | C29: 0 | D29: 0 | E29: 0 | F29: 0 | G29: 0 | H29: 0 | I29: 0 | K29: 0
A30: OLFD | B30: 0 | C30: 0 | D30: 0 | E30: 0 | F30: 0 | G30: 0 | H30: 0 | I30: 0 | K30: 0
A31: OMD | B31: 0 | C31: 0 | D31: 0 | E31: 0 | F31: 0 | G31: 0 | H31: 0 | I31: 0 | K31: 0
A32: ORFD | B32: 0 | C32: 0 | D32: 0 | E32: 0 | F32: 0 | G32: 0 | H32: 0 | I32: 0 | K32: 0
A33: RSD | B33: 0 | C33: 0 | D33: 0 | E33: 0 | F33: 0 | G33: 0 | H33: 0 | I33: 0 | K33: 0
... A44: VUR | B44: 0 | C44: 0 | D44: 0 | E44: 0 | F44: 0 | G44: 0 | H44: 0 | I44: 0 | K44: 0
A45: VVR | B45: 1 | C45: 0 | D45: 0 | E45: 1 | F45: 0 | G45: 1 | H45: 0 | I45: 0 | J45: 0 | K45: 2.22755
A46: All | B46: =SUM(B2:B45) | C46: =SUM(C2:C45) | D46: =SUM(D2:D45) | E46: =SUM(E2:E45) | F46: =SUM(F2:F45) | G46: =SUM(G2:G45) | H46: =SUM(H2:H45) | I46: =SUM(I2:I45) | J46: =(F46+I46)/B46*100 | K46: =SUM(K2:K45)

Sheet Cm_5000_0.01_no_pi
A1: Operator | B1: Total | C1: Equivalent | D1: Redundant | E1: Valid | F1: Killed | G1: Live | H1: Timedout | I1: Stillborn | J1: Mutation Score | K1: Testing Time
A2: ACM | B2: 0 | C2: 0 | D2: 0 | E2: 0 | F2: 0 | G2: 0 | H2: 0 | I2: 0 | K2: 0
A3: AOR | B3: 0 | C3: 0 | D3: 0 | E3: 0 | F3: 0 | G3: 0 | H3: 0 | I3: 0 | K3: 0
A4: AVR | B4: 1 | C4: 0 | D4: 0 | E4: 1 | F4: 1 | G4: 0 | H4: 0 | I4: 0 | J4: 100 | K4: 0.24991667
A5: BCRD | B5: 0 | C5: 0 | D5: 0 | E5: 0 | F5: 0 | G5: 0 | H5: 0 | I5: 0 | K5: 0
A6: BLR | B6: 10 | C6: 0 | D6: 0 | E6: 10 | F6: 9 | G6: 1 | H6: 0 | I6: 0 | J6: 90 | K6: 8.0448167
A7: BOR | B7: 41 | C7: 0 | D7: 0 | E7: 41 | F7: 37 | G7: 4 | H7: 0 | I7: 0 | J7: 90.243902 | K7: 31.954383
A8: CBD | B8: 0 | C8: 0 | D8: 0 | E8: 0 | F8: 0 | G8: 0 | H8: 0 | I8: 0 | K8: 0
A9: CCD | B9: 2 | C9: 0 | D9: 0 | E9: 2 | F9: 2 | G9: 0 | H9: 0 | I9: 0 | J9: 100 | K9: 0.43305
A10: CSC | B10: 30 | C10: 0 | D10: 0 | E10: 30 | F10: 22 | G10: 8 | H10: 0 | I10: 0 | J10: 73.333333 | K10: 52.57255
A11: DLR | B11: 3 | C11: 0 | D11: 0 | E11: 0 | F11: 0 | G11: 0 | H11: 0 | I11: 3 | K11: 0
A12: DOD | B12: 0 | C12: 0 | D12: 0 | E12: 0 | F12: 0 | G12: 0 | H12: 0 | I12: 0 | K12: 0
A13: ECS | B13: 0 | C13: 0 | D13: 0 | E13: 0 | F13: 0 | G13: 0 | H13: 0 | I13: 0 | K13: 0
A14: EED | B14: 0 | C14: 0 | D14: 0 | E14: 0 | F14: 0 | G14: 0 | H14: 0 | I14: 0 | K14: 0
A15: EHC | B15: 20 | C15: 0 | D15: 0 | E15: 20 | F15: 8 | G15: 12 | H15: 0 | I15: 0 | J15: 40 | K15: 75.54465
A16: ER | B16: 9 | C16: 0 | D16: 0 | E16: 9 | F16: 6 | G16: 3 | H16: 0 | I16: 0 | J16: 66.666667 | K16: 19.656183
A17: ETR | B17: 2 | C17: 0 | D17: 0 | E17: 0 | F17: 0 | G17: 0 | H17: 0 | I17: 2 | K17: 0
A18: FVR | B18: 8 | C18: 0 | D18: 0 | E18: 6 | F18: 6 | G18: 0 | H18: 0 | I18: 2 | J18: 100 | K18: 1.3269833
A19: GVR | B19: 0 | C19: 0 | D19: 0 | E19: 0 | F19: 0 | G19: 0 | H19: 0 | I19: 0 | K19: 0
A20: HLR | B20: 0 | C20: 0 | D20: 0 | E20: 0 | F20: 0 | G20: 0 | H20: 0 | I20: 0 | K20: 0
A21: ILR | B21: 7 | C21: 0 | D21: 0 | E21: 7 | F21: 6 | G21: 1 | H21: 0 | I21: 0 | J21: 85.714286 | K21: 7.5875833
A22: ICM | B22: 0 | C22: 0 | D22: 0 | E22: 0 | F22: 0 | G22: 0 | H22: 0 | I22: 0 | K22: 0
A23: LSC | B23: 0 | C23: 0 | D23: 0 | E23: 0 | F23: 0 | G23: 0 | H23: 0 | I23: 0 | K23: 0
A24: PKD | B24: 0 | C24: 0 | D24: 0 | E24: 0 | F24: 0 | G24: 0 | H24: 0 | I24: 0 | K24: 0
A25: MCR | B25: 0 | C25: 0 | D25: 0 | E25: 0 | F25: 0 | G25: 0 | H25: 0 | I25: 0 | K25: 0
A26: MOC | B26: 0 | C26: 0 | D26: 0 | E26: 0 | F26: 0 | G26: 0 | H26: 0 | I26: 0 | K26: 0
A27: MOD | B27: 0 | C27: 0 | D27: 0 | E27: 0 | F27: 0 | G27: 0 | H27: 0 | I27: 0 | K27: 0
A28: MOI | B28: 0 | C28: 0 | D28: 0 | E28: 0 | F28: 0 | G28: 0 | H28: 0 | I28: 0 | K28: 0
A29: MOR | B29: 0 | C29: 0 | D29: 0 | E29: 0 | F29: 0 | G29: 0 | H29: 0 | I29: 0 | K29: 0
A30: OLFD | B30: 0 | C30: 0 | D30: 0 | E30: 0 | F30: 0 | G30: 0 | H30: 0 | I30: 0 | K30: 0
A31: OMD | B31: 0 | C31: 0 | D31: 0 | E31: 0 | F31: 0 | G31: 0 | H31: 0 | I31: 0 | K31: 0
A32: ORFD | B32: 0 | C32: 0 | D32: 0 | E32: 0 | F32: 0 | G32: 0 | H32: 0 | I32: 0 | K32: 0
A33: RSD | B33: 0 | C33: 0 | D33: 0 | E33: 0 | F33: 0 | G33: 0 | H33: 0 | I33: 0 | K33: 0
... A42: TOR | B42: 0 | C42: 0 | D42: 0 | E42: 0 | F42: 0 | G42: 0 | H42: 0 | I42: 0 | K42: 0
A43: UORD | B43: 1 | C43: 0 | D43: 0 | E43: 1 | F43: 1 | G43: 0 | H43: 0 | I43: 0 | J43: 100 | K43: 0.23601667
A44: VUR | B44: 0 | C44: 0 | D44: 0 | E44: 0 | F44: 0 | G44: 0 | H44: 0 | I44: 0 | K44: 0
A45: VVR | B45: 12 | C45: 0 | D45: 0 | E45: 12 | F45: 4 | G45: 8 | H45: 0 | I45: 0 | J45: 33.333333 | K45: 48.537967
A46: All | B46: =SUM(B2:B45) | C46: =SUM(C2:C45) | D46: =SUM(D2:D45) | E46: =SUM(E2:E45) | F46: =SUM(F2:F45) | G46: =SUM(G2:G45) | H46: =SUM(H2:H45) | I46: =SUM(I2:I45) | J46: =(F46+I46)/B46*100 | K46: =SUM(K2:K45)

Sheet DefectiveCounter_10000_0.01_no_pi
A1: Operator | B1: Total | C1: Equivalent | D1: Redundant | E1: Valid | F1: Killed | G1: Live | H1: Timedout | I1: Stillborn | J1: Mutation Score | K1: Testing Time
A2: ACM | B2: 0 | C2: 0 | D2: 0 | E2: 0 | F2: 0 | G2: 0 | H2: 0 | I2: 0 | K2: 0
A3: AOR | B3: 0 | C3: 0 | D3: 0 | E3: 0 | F3: 0 | G3: 0 | H3: 0 | I3: 0 | K3: 0
A4: AVR | B4: 0 | C4: 0 | D4: 0 | E4: 0 | F4: 0 | G4: 0 | H4: 0 | I4: 0 | K4: 0
A5: BCRD | B5: 0 | C5: 0 | D5: 0 | E5: 0 | F5: 0 | G5: 0 | H5: 0 | I5: 0 | K5: 0
A6: BLR | B6: 4 | C6: 0 | D6: 0 | E6: 4 | F6: 4 | G6: 0 | H6: 0 | I6: 0 | J6: 100 | K6: 0.8299
A7: BOR | B7: 3 | C7: 0 | D7: 0 | E7: 3 | F7: 3 | G7: 0 | H7: 0 | I7: 0 | J7: 100 | K7: 0.61906667
A8: CBD | B8: 0 | C8: 0 | D8: 0 | E8: 0 | F8: 0 | G8: 0 | H8: 0 | I8: 0 | K8: 0
A9: CCD | B9: 1 | C9: 0 | D9: 0 | E9: 1 | F9: 1 | G9: 0 | H9: 0 | I9: 0 | J9: 100 | K9: 0.20095
A10: CSC | B10: 6 | C10: 0 | D10: 0 | E10: 6 | F10: 4 | G10: 2 | H10: 0 | I10: 0 | J10: 66.666667 | K10: 2.0602
A11: DLR | B11: 1 | C11: 0 | D11: 0 | E11: 0 | F11: 0 | G11: 0 | H11: 0 | I11: 1 | K11: 0
A12: DOD | B12: 0 | C12: 0 | D12: 0 | E12: 0 | F12: 0 | G12: 0 | H12: 0 | I12: 0 | K12: 0
A13: ECS | B13: 0 | C13: 0 | D13: 0 | E13: 0 | F13: 0 | G13: 0 | H13: 0 | I13: 0 | K13: 0
A14: EED | B14: 0 | C14: 0 | D14: 0 | E14: 0 | F14: 0 | G14: 0 | H14: 0 | I14: 0 | K14: 0
A15: EHC | B15: 6 | C15: 0 | D15: 0 | E15: 6 | F15: 1 | G15: 5 | H15: 0 | I15: 0 | J15: 16.666667 | K15: 3.4104333
A16: ER | B16: 4 | C16: 0 | D16: 0 | E16: 4 | F16: 2 | G16: 2 | H16: 0 | I16: 0 | J16: 50 | K16: 1.6982833
A17: ETR | B17: 0 | C17: 0 | D17: 0 | E17: 0 | F17: 0 | G17: 0 | H17: 0 | I17: 0 | K17: 0
A18: FVR | B18: 1 | C18: 0 | D18: 0 | E18: 1 | F18: 1 | G18: 0 | H18: 0 | I18: 0 | J18: 100 | K18: 0.20426667
A19: GVR | B19: 0 | C19: 0 | D19: 0 | E19: 0 | F19: 0 | G19: 0 | H19: 0 | I19: 0 | K19: 0
A20: HLR | B20: 0 | C20: 0 | D20: 0 | E20: 0 | F20: 0 | G20: 0 | H20: 0 | I20: 0 | K20: 0
A21: ILR | B21: 3 | C21: 0 | D21: 0 | E21: 3 | F21: 3 | G21: 0 | H21: 0 | I21: 0 | J21: 100 | K21: 0.61116667
A22: ICM | B22: 0 | C22: 0 | D22: 0 | E22: 0 | F22: 0 | G22: 0 | H22: 0 | I22: 0 | K22: 0
A23: LSC | B23: 0 | C23: 0 | D23: 0 | E23: 0 | F23: 0 | G23: 0 | H23: 0 | I23: 0 | K23: 0
A24: PKD | B24: 0 | C24: 0 | D24: 0 | E24: 0 | F24: 0 | G24: 0 | H24: 0 | I24: 0 | K24: 0
A25: MCR | B25: 0 | C25: 0 | D25: 0 | E25: 0 | F25: 0 | G25: 0 | H25: 0 | I25: 0 | K25: 0
A26: MOC | B26: 0 | C26: 0 | D26: 0 | E26: 0 | F26: 0 | G26: 0 | H26: 0 | I26: 0 | K26: 0
A27: MOD | B27: 0 | C27: 0 | D27: 0 | E27: 0 | F27: 0 | G27: 0 | H27: 0 | I27: 0 | K27: 0
A28: MOI | B28: 0 | C28: 0 | D28: 0 | E28: 0 | F28: 0 | G28: 0 | H28: 0 | I28: 0 | K28: 0
A29: MOR | B29: 0 | C29: 0 | D29: 0 | E29: 0 | F29: 0 | G29: 0 | H29: 0 | I29: 0 | K29: 0
A30: OLFD | B30: 0 | C30: 0 | D30: 0 | E30: 0 | F30: 0 | G30: 0 | H30: 0 | I30: 0 | K30: 0
A31: OMD | B31: 0 | C31: 0 | D31: 0 | E31: 0 | F31: 0 | G31: 0 | H31: 0 | I31: 0 | K31: 0
A32: ORFD | B32: 0 | C32: 0 | D32: 0 | E32: 0 | F32: 0 | G32: 0 | H32: 0 | I32: 0 | K32: 0
A33: RSD | B33: 0 | C33: 0 | D33: 0 | E33: 0 | F33: 0 | G33: 0 | H33: 0 | I33: 0 | K33: 0
... A44: VUR | B44: 0 | C44: 0 | D44: 0 | E44: 0 | F44: 0 | G44: 0 | H44: 0 | I44: 0 | K44: 0
A45: VVR | B45: 3 | C45: 0 | D45: 0 | E45: 3 | F45: 1 | G45: 2 | H45: 0 | I45: 0 | J45: 33.333333 | K45: 1.4879
A46: All | B46: =SUM(B2:B45) | C46: =SUM(C2:C45) | D46: =SUM(D2:D45) | E46: =SUM(E2:E45) | F46: =SUM(F2:F45) | G46: =SUM(G2:G45) | H46: =SUM(H2:H45) | I46: =SUM(I2:I45) | J46: =(F46+I46)/B46*100 | K46: =SUM(K2:K45)

Sheet DefectiveCounter_10000_0.5_no_pi
A1: Operator | B1: Total | C1: Equivalent | D1: Redundant | E1: Valid | F1: Killed | G1: Live | H1: Timedout | I1: Stillborn | J1: Mutation Score | K1: Testing Time
A2: ACM | B2: 0 | C2: 0 | D2: 0 | E2: 0 | F2: 0 | G2: 0 | H2: 0 | I2: 0 | K2: 0
A3: AOR | B3: 0 | C3: 0 | D3: 0 | E3: 0 | F3: 0 | G3: 0 | H3: 0 | I3: 0 | K3: 0
A4: AVR | B4: 0 | C4: 0 | D4: 0 | E4: 0 | F4: 0 | G4: 0 | H4: 0 | I4: 0 | K4: 0
A5: BCRD | B5: 0 | C5: 0 | D5: 0 | E5: 0 | F5: 0 | G5: 0 | H5: 0 | I5: 0 | K5: 0
A6: BLR | B6: 4 | C6: 0 | D6: 0 | E6: 4 | F6: 4 | G6: 0 | H6: 0 | I6: 0 | J6: 100 | K6: 0.83751667
A7: BOR | B7: 3 | C7: 0 | D7: 0 | E7: 3 | F7: 3 | G7: 0 | H7: 0 | I7: 0 | J7: 100 | K7: 0.62848333
A8: CBD | B8: 0 | C8: 0 | D8: 0 | E8: 0 | F8: 0 | G8: 0 | H8: 0 | I8: 0 | K8: 0
A9: CCD | B9: 1 | C9: 0 | D9: 0 | E9: 1 | F9: 1 | G9: 0 | H9: 0 | I9: 0 | J9: 100 | K9: 0.21031667
A10: CSC | B10: 6 | C10: 0 | D10: 0 | E10: 6 | F10: 4 | G10: 2 | H10: 0 | I10: 0 | J10: 66.666667 | K10: 2.4984
A11: DLR | B11: 1 | C11: 0 | D11: 0 | E11: 0 | F11: 0 | G11: 0 | H11: 0 | I11: 1 | K11: 0
A12: DOD | B12: 0 | C12: 0 | D12: 0 | E12: 0 | F12: 0 | G12: 0 | H12: 0 | I12: 0 | K12: 0
A13: ECS | B13: 0 | C13: 0 | D13: 0 | E13: 0 | F13: 0 | G13: 0 | H13: 0 | I13: 0 | K13: 0
A14: EED | B14: 0 | C14: 0 | D14: 0 | E14: 0 | F14: 0 | G14: 0 | H14: 0 | I14: 0 | K14: 0
A15: EHC | B15: 6 | C15: 0 | D15: 0 | E15: 6 | F15: 1 | G15: 5 | H15: 0 | I15: 0 | J15: 16.666667 | K15: 4.34705
A16: ER | B16: 4 | C16: 0 | D16: 0 | E16: 4 | F16: 2 | G16: 2 | H16: 0 | I16: 0 | J16: 50 | K16: 2.0503833
A17: ETR | B17: 0 | C17: 0 | D17: 0 | E17: 0 | F17: 0 | G17: 0 | H17: 0 | I17: 0 | K17: 0
A18: FVR | B18: 1 | C18: 0 | D18: 0 | E18: 1 | F18: 1 | G18: 0 | H18: 0 | I18: 0 | J18: 100 | K18: 0.20311667
A19: GVR | B19: 0 | C19: 0 | D19: 0 | E19: 0 | F19: 0 | G19: 0 | H19: 0 | I19: 0 | K19: 0
A20: HLR | B20: 0 | C20: 0 | D20: 0 | E20: 0 | F20: 0 | G20: 0 | H20: 0 | I20: 0 | K20: 0
A21: ILR | B21: 3 | C21: 0 | D21: 0 | E21: 3 | F21: 3 | G21: 0 | H21: 0 | I21: 0 | J21: 100 | K21: 0.61145
A22: ICM | B22: 0 | C22: 0 | D22: 0 | E22: 0 | F22: 0 | G22: 0 | H22: 0 | I22: 0 | K22: 0
A23: LSC | B23: 0 | C23: 0 | D23: 0 | E23: 0 | F23: 0 | G23: 0 | H23: 0 | I23: 0 | K23: 0
A24: PKD | B24: 0 | C24: 0 | D24: 0 | E24: 0 | F24: 0 | G24: 0 | H24: 0 | I24: 0 | K24: 0
A25: MCR | B25: 0 | C25: 0 | D25: 0 | E25: 0 | F25: 0 | G25: 0 | H25: 0 | I25: 0 | K25: 0
A26: MOC | B26: 0 | C26: 0 | D26: 0 | E26: 0 | F26: 0 | G26: 0 | H26: 0 | I26: 0 | K26: 0
A27: MOD | B27: 0 | C27: 0 | D27: 0 | E27: 0 | F27: 0 | G27: 0 | H27: 0 | I27: 0 | K27: 0
A28: MOI | B28: 0 | C28: 0 | D28: 0 | E28: 0 | F28: 0 | G28: 0 | H28: 0 | I28: 0 | K28: 0
A29: MOR | B29: 0 | C29: 0 | D29: 0 | E29: 0 | F29: 0 | G29: 0 | H29: 0 | I29: 0 | K29: 0
A30: OLFD | B30: 0 | C30: 0 | D30: 0 | E30: 0 | F30: 0 | G30: 0 | H30: 0 | I30: 0 | K30: 0
A31: OMD | B31: 0 | C31: 0 | D31: 0 | E31: 0 | F31: 0 | G31: 0 | H31: 0 | I31: 0 | K31: 0
A32: ORFD | B32: 0 | C32: 0 | D32: 0 | E32: 0 | F32: 0 | G32: 0 | H32: 0 | I32: 0 | K32: 0
A33: RSD | B33: 0 | C33: 0 | D33: 0 | E33: 0 | F33: 0 | G33: 0 | H33: 0 | I33: 0 | K33: 0
... A44: VUR | B44: 0 | C44: 0 | D44: 0 | E44: 0 | F44: 0 | G44: 0 | H44: 0 | I44: 0 | K44: 0
A45: VVR | B45: 3 | C45: 0 | D45: 0 | E45: 3 | F45: 1 | G45: 2 | H45: 0 | I45: 0 | J45: 33.333333 | K45: 1.7703833
A46: All | B46: =SUM(B2:B45) | C46: =SUM(C2:C45) | D46: =SUM(D2:D45) | E46: =SUM(E2:E45) | F46: =SUM(F2:F45) | G46: =SUM(G2:G45) | H46: =SUM(H2:H45) | I46: =SUM(I2:I45) | J46: =(F46+I46)/B46*100 | K46: =SUM(K2:K45)

Sheet FrequentFlyer_10000_0.01_no_pi
A1: Operator | B1: Total | C1: Equivalent | D1: Redundant | E1: Valid | F1: Killed | G1: Live | H1: Timedout | I1: Stillborn | J1: Mutation Score | K1: Testing Time
A2: ACM | B2: 0 | C2: 0 | D2: 0 | E2: 0 | F2: 0 | G2: 0 | H2: 0 | I2: 0 | K2: 0
A3: AOR | B3: 6 | C3: 0 | D3: 0 | E3: 6 | F3: 6 | G3: 0 | H3: 0 | I3: 0 | J3: 100 | K3: 1.3552167
A4: AVR | B4: 0 | C4: 0 | D4: 0 | E4: 0 | F4: 0 | G4: 0 | H4: 0 | I4: 0 | K4: 0
A5: BCRD | B5: 0 | C5: 0 | D5: 0 | E5: 0 | F5: 0 | G5: 0 | H5: 0 | I5: 0 | K5: 0
A6: BLR | B6: 8 | C6: 0 | D6: 0 | E6: 8 | F6: 7 | G6: 1 | H6: 0 | I6: 0 | J6: 87.5 | K6: 6.9317
A7: BOR | B7: 23 | C7: 0 | D7: 0 | E7: 23 | F7: 20 | G7: 3 | H7: 0 | I7: 0 | J7: 86.956522 | K7: 17.629
A8: CBD | B8: 0 | C8: 0 | D8: 0 | E8: 0 | F8: 0 | G8: 0 | H8: 0 | I8: 0 | K8: 0
A9: CCD | B9: 1 | C9: 0 | D9: 0 | E9: 1 | F9: 1 | G9: 0 | H9: 0 | I9: 0 | J9: 100 | K9: 0.2121
A10: CSC | B10: 12 | C10: 0 | D10: 0 | E10: 12 | F10: 8 | G10: 4 | H10: 0 | I10: 0 | J10: 66.666667 | K10: 19.533417
A11: DLR | B11: 5 | C11: 0 | D11: 0 | E11: 0 | F11: 0 | G11: 0 | H11: 0 | I11: 5 | K11: 0
A12: DOD | B12: 0 | C12: 0 | D12: 0 | E12: 0 | F12: 0 | G12: 0 | H12: 0 | I12: 0 | K12: 0
A13: ECS | B13: 0 | C13: 0 | D13: 0 | E13: 0 | F13: 0 | G13: 0 | H13: 0 | I13: 0 | K13: 0
A14: EED | B14: 0 | C14: 0 | D14: 0 | E14: 0 | F14: 0 | G14: 0 | H14: 0 | I14: 0 | K14: 0
A15: EHC | B15: 4 | C15: 0 | D15: 0 | E15: 4 | F15: 1 | G15: 3 | H15: 0 | I15: 0 | J15: 25 | K15: 13.644083
A16: ER | B16: 7 | C16: 0 | D16: 0 | E16: 7 | F16: 2 | G16: 5 | H16: 0 | I16: 0 | J16: 28.571429 | K16: 22.62165
A17: ETR | B17: 0 | C17: 0 | D17: 0 | E17: 0 | F17: 0 | G17: 0 | H17: 0 | I17: 0 | K17: 0
A18: FVR | B18: 4 | C18: 0 | D18: 0 | E18: 4 | F18: 1 | G18: 3 | H18: 0 | I18: 0 | J18: 25 | K18: 14.373883
A19: GVR | B19: 0 | C19: 0 | D19: 0 | E19: 0 | F19: 0 | G19: 0 | H19: 0 | I19: 0 | K19: 0
A20: HLR | B20: 0 | C20: 0 | D20: 0 | E20: 0 | F20: 0 | G20: 0 | H20: 0 | I20: 0 | K20: 0
A21: ILR | B21: 16 | C21: 0 | D21: 0 | E21: 16 | F21: 13 | G21: 3 | H21: 0 | I21: 0 | J21: 81.25 | K21: 18.142567
A22: ICM | B22: 0 | C22: 0 | D22: 0 | E22: 0 | F22: 0 | G22: 0 | H22: 0 | I22: 0 | K22: 0
A23: LSC | B23: 10 | C23: 0 | D23: 0 | E23: 10 | F23: 7 | G23: 3 | H23: 0 | I23: 0 | J23: 70 | K23: 15.9466
A24: PKD | B24: 0 | C24: 0 | D24: 0 | E24: 0 | F24: 0 | G24: 0 | H24: 0 | I24: 0 | K24: 0
A25: MCR | B25: 0 | C25: 0 | D25: 0 | E25: 0 | F25: 0 | G25: 0 | H25: 0 | I25: 0 | K25: 0
A26: MOC | B26: 0 | C26: 0 | D26: 0 | E26: 0 | F26: 0 | G26: 0 | H26: 0 | I26: 0 | K26: 0
A27: MOD | B27: 0 | C27: 0 | D27: 0 | E27: 0 | F27: 0 | G27: 0 | H27: 0 | I27: 0 | K27: 0
A28: MOI | B28: 0 | C28: 0 | D28: 0 | E28: 0 | F28: 0 | G28: 0 | H28: 0 | I28: 0 | K28: 0
A29: MOR | B29: 0 | C29: 0 | D29: 0 | E29: 0 | F29: 0 | G29: 0 | H29: 0 | I29: 0 | K29: 0
A30: OLFD | B30: 0 | C30: 0 | D30: 0 | E30: 0 | F30: 0 | G30: 0 | H30: 0 | I30: 0 | K30: 0
A31: OMD | B31: 0 | C31: 0 | D31: 0 | E31: 0 | F31: 0 | G31: 0 | H31: 0 | I31: 0 | K31: 0
A32: ORFD | B32: 0 | C32: 0 | D32: 0 | E32: 0 | F32: 0 | G32: 0 | H32: 0 | I32: 0 | K32: 0
A33: RSD | B33: 4 | C33: 0 | D33: 0 | E33: 4 | F33: 3 | G33: 1 | H33: 0 | I33: 0 | J33: 75 | K33: 5.2931
A34: RVS | B34: 0 | C34: 0 | D34: 0 | E34: 0 | F34: 0 | G34: 0 | H34: 0 | I34: 0 | K34: 0
A35: SCEC | B35: 0 | C35: 0 | D35: 0 | E35: 0 | F35: 0 | G35: 0 | H35: 0 | I35: 0 | K35: 0
A36: SFI | B36: 0 | C36: 0 | D36: 0 | E36: 0 | F36: 0 | G36: 0 | H36: 0 | I36: 0 | K36: 0
A37: SFD | B37: 0 | C37: 0 | D37: 0 | E37: 0 | F37: 0 | G37: 0 | H37: 0 | I37: 0 | K37: 0
A38: SFR | B38: 0 | C38: 0 | D38: 0 | E38: 0 | F38: 0 | G38: 0 | H38: 0 | I38: 0 | K38: 0
A39: SKD | B39: 0 | C39: 0 | D39: 0 | E39: 0 | F39: 0 | G39: 0 | H39: 0 | I39: 0 | K39: 0
A40: SKI | B40: 0 | C40: 0 | D40: 0 | E40: 0 | F40: 0 | G40: 0 | H40: 0 | I40: 0 | K40: 0
...

Sheet FrequentFlyer_10000_0.5_no_pi
A1: Operator | B1: Total | C1: Equivalent | D1: Redundant | E1: Valid | F1: Killed | G1: Live | H1: Timedout | I1: Stillborn | J1: Mutation Score | K1: Testing Time
A2: ACM | B2: 0 | C2: 0 | D2: 0 | E2: 0 | F2: 0 | G2: 0 | H2: 0 | I2: 0 | K2: 0
A3: AOR | B3: 4 | C3: 0 | D3: 0 | E3: 4 | F3: 4 | G3: 0 | H3: 0 | I3: 0 | J3: 100 | K3: 0.83791667
A4: AVR | B4: 0 | C4: 0 | D4: 0 | E4: 0 | F4: 0 | G4: 0 | H4: 0 | I4: 0 | K4: 0
A5: BCRD | B5: 0 | C5: 0 | D5: 0 | E5: 0 | F5: 0 | G5: 0 | H5: 0 | I5: 0 | K5: 0
A6: BLR | B6: 5 | C6: 0 | D6: 0 | E6: 5 | F6: 5 | G6: 0 | H6: 0 | I6: 0 | J6: 100 | K6: 1.0455
A7: BOR | B7: 17 | C7: 0 | D7: 0 | E7: 17 | F7: 14 | G7: 3 | H7: 0 | I7: 0 | J7: 82.352941 | K7: 13.166833
A8: CBD | B8: 0 | C8: 0 | D8: 0 | E8: 0 | F8: 0 | G8: 0 | H8: 0 | I8: 0 | K8: 0
A9: CCD | B9: 1 | C9: 0 | D9: 0 | E9: 1 | F9: 1 | G9: 0 | H9: 0 | I9: 0 | J9: 100 | K9: 0.21253333
A10: CSC | B10: 8 | C10: 0 | D10: 0 | E10: 8 | F10: 6 | G10: 2 | H10: 0 | I10: 0 | J10: 75 | K10: 8.26285
A11: DLR | B11: 1 | C11: 0 | D11: 0 | E11: 0 | F11: 0 | G11: 0 | H11: 0 | I11: 1 | K11: 0
A12: DOD | B12: 0 | C12: 0 | D12: 0 | E12: 0 | F12: 0 | G12: 0 | H12: 0 | I12: 0 | K12: 0
A13: ECS | B13: 0 | C13: 0 | D13: 0 | E13: 0 | F13: 0 | G13: 0 | H13: 0 | I13: 0 | K13: 0
A14: EED | B14: 0 | C14: 0 | D14: 0 | E14: 0 | F14: 0 | G14: 0 | H14: 0 | I14: 0 | K14: 0
A15: EHC | B15: 4 | C15: 0 | D15: 0 | E15: 4 | F15: 1 | G15: 3 | H15: 0 | I15: 0 | J15: 25 | K15: 10.757133
A16: ER | B16: 7 | C16: 0 | D16: 0 | E16: 7 | F16: 2 | G16: 5 | H16: 0 | I16: 0 | J16: 28.571429 | K16: 17.781967
A17: ETR | B17: 0 | C17: 0 | D17: 0 | E17: 0 | F17: 0 | G17: 0 | H17: 0 | I17: 0 | K17: 0
A18: FVR | B18: 1 | C18: 0 | D18: 0 | E18: 1 | F18: 1 | G18: 0 | H18: 0 | I18: 0 | J18: 100 | K18: 0.20951667
A19: GVR | B19: 0 | C19: 0 | D19: 0 | E19: 0 | F19: 0 | G19: 0 | H19: 0 | I19: 0 | K19: 0
A20: HLR | B20: 0 | C20: 0 | D20: 0 | E20: 0 | F20: 0 | G20: 0 | H20: 0 | I20: 0 | K20: 0
A21: ILR | B21: 10 | C21: 0 | D21: 0 | E21: 10 | F21: 8 | G21: 2 | H21: 0 | I21: 0 | J21: 80 | K21: 8.4198333
A22: ICM | B22: 0 | C22: 0 | D22: 0 | E22: 0 | F22: 0 | G22: 0 | H22: 0 | I22: 0 | K22: 0
A23: LSC | B23: 4 | C23: 0 | D23: 0 | E23: 4 | F23: 2 | G23: 2 | H23: 0 | I23: 0 | J23: 50 | K23: 6.8802667
A24: PKD | B24: 0 | C24: 0 | D24: 0 | E24: 0 | F24: 0 | G24: 0 | H24: 0 | I24: 0 | K24: 0
A25: MCR | B25: 0 | C25: 0 | D25: 0 | E25: 0 | F25: 0 | G25: 0 | H25: 0 | I25: 0 | K25: 0
A26: MOC | B26: 0 | C26: 0 | D26: 0 | E26: 0 | F26: 0 | G26: 0 | H26: 0 | I26: 0 | K26: 0
A27: MOD | B27: 0 | C27: 0 | D27: 0 | E27: 0 | F27: 0 | G27: 0 | H27: 0 | I27: 0 | K27: 0
A28: MOI | B28: 0 | C28: 0 | D28: 0 | E28: 0 | F28: 0 | G28: 0 | H28: 0 | I28: 0 | K28: 0
A29: MOR | B29: 0 | C29: 0 | D29: 0 | E29: 0 | F29: 0 | G29: 0 | H29: 0 | I29: 0 | K29: 0
A30: OLFD | B30: 0 | C30: 0 | D30: 0 | E30: 0 | F30: 0 | G30: 0 | H30: 0 | I30: 0 | K30: 0
A31: OMD | B31: 0 | C31: 0 | D31: 0 | E31: 0 | F31: 0 | G31: 0 | H31: 0 | I31: 0 | K31: 0
A32: ORFD | B32: 0 | C32: 0 | D32: 0 | E32: 0 | F32: 0 | G32: 0 | H32: 0 | I32: 0 | K32: 0
A33: RSD | B33: 0 | C33: 0 | D33: 0 | E33: 0 | F33: 0 | G33: 0 | H33: 0 | I33: 0 | K33: 0
A34: RVS | B34: 0 | C34: 0 | D34: 0 | E34: 0 | F34: 0 | G34: 0 | H34: 0 | I34: 0 | K34: 0
A35: SCEC | B35: 0 | C35: 0 | D35: 0 | E35: 0 | F35: 0 | G35: 0 | H35: 0 | I35: 0 | K35: 0
... A44: VUR | B44: 0 | C44: 0 | D44: 0 | E44: 0 | F44: 0 | G44: 0 | H44: 0 | I44: 0 | K44: 0
A45: VVR | B45: 5 | C45: 0 | D45: 0 | E45: 5 | F45: 3 | G45: 2 | H45: 0 | I45: 0 | J45: 60 | K45: 6.8984833
A46: All | B46: =SUM(B2:B45) | C46: =SUM(C2:C45) | D46: =SUM(D2:D45) | E46: =SUM(E2:E45) | F46: =SUM(F2:F45) | G46: =SUM(G2:G45) | H46: =SUM(H2:H45) | I46: =SUM(I2:I45) | J46: =(F46+I46)/B46*100 | K46: =SUM(K2:K45)

Sheet HelloBlockchain_10000_0.01_no_pi
A1: Operator | B1: Total | C1: Equivalent | D1: Redundant | E1: Valid | F1: Killed | G1: Live | H1: Timedout | I1: Stillborn | J1: Mutation Score | K1: Testing Time
A2: ACM | B2: 0 | C2: 0 | D2: 0 | E2: 0 | F2: 0 | G2: 0 | H2: 0 | I2: 0 | K2: 0
A3: AOR | B3: 0 | C3: 0 | D3: 0 | E3: 0 | F3: 0 | G3: 0 | H3: 0 | I3: 0 | K3: 0
A4: AVR | B4: 0 | C4: 0 | D4: 0 | E4: 0 | F4: 0 | G4: 0 | H4: 0 | I4: 0 | K4: 0
A5: BCRD | B5: 0 | C5: 0 | D5: 0 | E5: 0 | F5: 0 | G5: 0 | H5: 0 | I5: 0 | K5: 0
A6: BLR | B6: 5 | C6: 0 | D6: 0 | E6: 5 | F6: 5 | G6: 0 | H6: 0 | I6: 0 | J6: 100 | K6: 1.0490167
A7: BOR | B7: 5 | C7: 0 | D7: 0 | E7: 5 | F7: 4 | G7: 1 | H7: 0 | I7: 0 | J7: 80 | K7: 2.0902667
A8: CBD | B8: 0 | C8: 0 | D8: 0 | E8: 0 | F8: 0 | G8: 0 | H8: 0 | I8: 0 | K8: 0
A9: CCD | B9: 1 | C9: 0 | D9: 0 | E9: 1 | F9: 1 | G9: 0 | H9: 0 | I9: 0 | J9: 100 | K9: 0.2068
A10: CSC | B10: 9 | C10: 0 | D10: 0 | E10: 9 | F10: 5 | G10: 4 | H10: 0 | I10: 0 | J10: 55.555556 | K10: 6.0864
A11: DLR | B11: 3 | C11: 0 | D11: 0 | E11: 0 | F11: 0 | G11: 0 | H11: 0 | I11: 3 | K11: 0
A12: DOD | B12: 0 | C12: 0 | D12: 0 | E12: 0 | F12: 0 | G12: 0 | H12: 0 | I12: 0 | K12: 0
A13: ECS | B13: 0 | C13: 0 | D13: 0 | E13: 0 | F13: 0 | G13: 0 | H13: 0 | I13: 0 | K13: 0
A14: EED | B14: 0 | C14: 0 | D14: 0 | E14: 0 | F14: 0 | G14: 0 | H14: 0 | I14: 0 | K14: 0
A15: EHC | B15: 7 | C15: 0 | D15: 0 | E15: 7 | F15: 1 | G15: 6 | H15: 0 | I15: 0 | J15: 14.285714 | K15: 7.7250333
A16: ER | B16: 7 | C16: 0 | D16: 0 | E16: 7 | F16: 4 | G16: 3 | H16: 0 | I16: 0 | J16: 57.142857 | K16: 4.6799167
A17: ETR | B17: 0 | C17: 0 | D17: 0 | E17: 0 | F17: 0 | G17: 0 | H17: 0 | I17: 0 | K17: 0
A18: FVR | B18: 2 | C18: 0 | D18: 0 | E18: 2 | F18: 2 | G18: 0 | H18: 0 | I18: 0 | J18: 100 | K18: 0.41435
A19: GVR | B19: 0 | C19: 0 | D19: 0 | E19: 0 | F19: 0 | G19: 0 | H19: 0 | I19: 0 | K19: 0
A20: HLR | B20: 0 | C20: 0 | D20: 0 | E20: 0 | F20: 0 | G20: 0 | H20: 0 | I20: 0 | K20: 0
A21: ILR | B21: 3 | C21: 0 | D21: 0 | E21: 3 | F21: 3 | G21: 0 | H21: 0 | I21: 0 | J21: 100 | K21: 0.6319
A22: ICM | B22: 0 | C22: 0 | D22: 0 | E22: 0 | F22: 0 | G22: 0 | H22: 0 | I22: 0 | K22: 0
A23: LSC | B23: 0 | C23: 0 | D23: 0 | E23: 0 | F23: 0 | G23: 0 | H23: 0 | I23: 0 | K23: 0
A24: PKD | B24: 0 | C24: 0 | D24: 0 | E24: 0 | F24: 0 | G24: 0 | H24: 0 | I24: 0 | K24: 0
A25: MCR | B25: 0 | C25: 0 | D25: 0 | E25: 0 | F25: 0 | G25: 0 | H25: 0 | I25: 0 | K25: 0
A26: MOC | B26: 0 | C26: 0 | D26: 0 | E26: 0 | F26: 0 | G26: 0 | H26: 0 | I26: 0 | K26: 0
A27: MOD | B27: 0 | C27: 0 | D27: 0 | E27: 0 | F27: 0 | G27: 0 | H27: 0 | I27: 0 | K27: 0
A28: MOI | B28: 0 | C28: 0 | D28: 0 | E28: 0 | F28: 0 | G28: 0 | H28: 0 | I28: 0 | K28: 0
A29: MOR | B29: 0 | C29: 0 | D29: 0 | E29: 0 | F29: 0 | G29: 0 | H29: 0 | I29: 0 | K29: 0
A30: OLFD | B30: 0 | C30: 0 | D30: 0 | E30: 0 | F30: 0 | G30: 0 | H30: 0 | I30: 0 | K30: 0
A31: OMD | B31: 0 | C31: 0 | D31: 0 | E31: 0 | F31: 0 | G31: 0 | H31: 0 | I31: 0 | K31: 0
A32: ORFD | B32: 0 | C32: 0 | D32: 0 | E32: 0 | F32: 0 | G32: 0 | H32: 0 | I32: 0 | K32: 0
A33: RSD | B33: 0 | C33: 0 | D33: 0 | E33: 0 | F33: 0 | G33: 0 | H33: 0 | I33: 0 | K33: 0
... A44: VUR | B44: 0 | C44: 0 | D44: 0 | E44: 0 | F44: 0 | G44: 0 | H44: 0 | I44: 0 | K44: 0
A45: VVR | B45: 3 | C45: 0 | D45: 0 | E45: 3 | F45: 2 | G45: 1 | H45: 0 | I45: 0 | J45: 66.666667 | K45: 1.6676333
A46: All | B46: =SUM(B2:B45) | C46: =SUM(C2:C45) | D46: =SUM(D2:D45) | E46: =SUM(E2:E45) | F46: =SUM(F2:F45) | G46: =SUM(G2:G45) | H46: =SUM(H2:H45) | I46: =SUM(I2:I45) | J46: =(F46+I46)/B46*100 | K46: =SUM(K2:K45)

Sheet RefrigeratedTransport_10000_0.01_no_pi
A1: Operator | B1: Total | C1: Equivalent | D1: Redundant | E1: Valid | F1: Killed | G1: Live | H1: Timedout | I1: Stillborn | J1: Mutation Score | K1: Testing Time
A2: ACM | B2: 0 | C2: 0 | D2: 0 | E2: 0 | F2: 0 | G2: 0 | H2: 0 | I2: 0 | K2: 0
A3: AOR | B3: 0 | C3: 0 | D3: 0 | E3: 0 | F3: 0 | G3: 0 | H3: 0 | I3: 0 | K3: 0
A4: AVR | B4: 0 | C4: 0 | D4: 0 | E4: 0 | F4: 0 | G4: 0 | H4: 0 | I4: 0 | K4: 0
A5: BCRD | B5: 0 | C5: 0 | D5: 0 | E5: 0 | F5: 0 | G5: 0 | H5: 0 | I5: 0 | K5: 0
A6: BLR | B6: 15 | C6: 0 | D6: 0 | E6: 15 | F6: 15 | G6: 0 | H6: 0 | I6: 0 | J6: 100 | K6: 3.17575
A7: BOR | B7: 69 | C7: 0 | D7: 0 | E7: 69 | F7: 54 | G7: 15 | H7: 0 | I7: 0 | J7: 78.26087 | K7: 40.451533
A8: CBD | B8: 0 | C8: 0 | D8: 0 | E8: 0 | F8: 0 | G8: 0 | H8: 0 | I8: 0 | K8: 0
A9: CCD | B9: 1 | C9: 0 | D9: 0 | E9: 1 | F9: 1 | G9: 0 | H9: 0 | I9: 0 | J9: 100 | K9: 0.21056667
A10: CSC | B10: 22 | C10: 0 | D10: 0 | E10: 22 | F10: 20 | G10: 2 | H10: 0 | I10: 0 | J10: 90.909091 | K10: 7.8253667
A11: DLR | B11: 0 | C11: 0 | D11: 0 | E11: 0 | F11: 0 | G11: 0 | H11: 0 | I11: 0 | K11: 0
A12: DOD | B12: 0 | C12: 0 | D12: 0 | E12: 0 | F12: 0 | G12: 0 | H12: 0 | I12: 0 | K12: 0
A13: ECS | B13: 0 | C13: 0 | D13: 0 | E13: 0 | F13: 0 | G13: 0 | H13: 0 | I13: 0 | K13: 0
A14: EED | B14: 0 | C14: 0 | D14: 0 | E14: 0 | F14: 0 | G14: 0 | H14: 0 | I14: 0 | K14: 0
A15: EHC | B15: 12 | C15: 0 | D15: 0 | E15: 12 | F15: 3 | G15: 9 | H15: 0 | I15: 0 | J15: 25 | K15: 16.623017
A16: ER | B16: 19 | C16: 0 | D16: 0 | E16: 19 | F16: 16 | G16: 3 | H16: 0 | I16: 0 | J16: 84.210526 | K16: 9.2955333
A17: ETR | B17: 0 | C17: 0 | D17: 0 | E17: 0 | F17: 0 | G17: 0 | H17: 0 | I17: 0 | K17: 0
A18: FVR | B18: 3 | C18: 0 | D18: 0 | E18: 3 | F18: 3 | G18: 0 | H18: 0 | I18: 0 | J18: 100 | K18: 0.61996667
A19: GVR | B19: 0 | C19: 0 | D19: 0 | E19: 0 | F19: 0 | G19: 0 | H19: 0 | I19: 0 | K19: 0
A20: HLR | B20: 0 | C20: 0 | D20: 0 | E20: 0 | F20: 0 | G20: 0 | H20: 0 | I20: 0 | K20: 0
A21: ILR | B21: 20 | C21: 0 | D21: 0 | E21: 20 | F21: 16 | G21: 4 | H21: 0 | I21: 0 | J21: 80 | K21: 10.915883
A22: ICM | B22: 0 | C22: 0 | D22: 0 | E22: 0 | F22: 0 | G22: 0 | H22: 0 | I22: 0 | K22: 0
A23: LSC | B23: 0 | C23: 0 | D23: 0 | E23: 0 | F23: 0 | G23: 0 | H23: 0 | I23: 0 | K23: 0
A24: PKD | B24: 0 | C24: 0 | D24: 0 | E24: 0 | F24: 0 | G24: 0 | H24: 0 | I24: 0 | K24: 0
A25: MCR | B25: 0 | C25: 0 | D25: 0 | E25: 0 | F25: 0 | G25: 0 | H25: 0 | I25: 0 | K25: 0
A26: MOC | B26: 0 | C26: 0 | D26: 0 | E26: 0 | F26: 0 | G26: 0 | H26: 0 | I26: 0 | K26: 0
A27: MOD | B27: 0 | C27: 0 | D27: 0 | E27: 0 | F27: 0 | G27: 0 | H27: 0 | I27: 0 | K27: 0
A28: MOI | B28: 0 | C28: 0 | D28: 0 | E28: 0 | F28: 0 | G28: 0 | H28: 0 | I28: 0 | K28: 0
A29: MOR | B29: 0 | C29: 0 | D29: 0 | E29: 0 | F29: 0 | G29: 0 | H29: 0 | I29: 0 | K29: 0
A30: OLFD | B30: 0 | C30: 0 | D30: 0 | E30: 0 | F30: 0 | G30: 0 | H30: 0 | I30: 0 | K30: 0
A31: OMD | B31: 0 | C31: 0 | D31: 0 | E31: 0 | F31: 0 | G31: 0 | H31: 0 | I31: 0 | K31: 0
A32: ORFD | B32: 0 | C32: 0 | D32: 0 | E32: 0 | F32: 0 | G32: 0 | H32: 0 | I32: 0 | K32: 0
A33: RSD | B33: 0 | C33: 0 | D33: 0 | E33: 0 | F33: 0 | G33: 0 | H33: 0 | I33: 0 | K33: 0
... A44: VUR | B44: 0 | C44: 0 | D44: 0 | E44: 0 | F44: 0 | G44: 0 | H44: 0 | I44: 0 | K44: 0
A45: VVR | B45: 7 | C45: 0 | D45: 0 | E45: 7 | F45: 6 | G45: 1 | H45: 0 | I45: 0 | J45: 85.714286 | K45: 3.1841333
A46: All | B46: =SUM(B2:B45) | C46: =SUM(C2:C45) | D46: =SUM(D2:D45) | E46: =SUM(E2:E45) | F46: =SUM(F2:F45) | G46: =SUM(G2:G45) | H46: =SUM(H2:H45) | I46: =SUM(I2:I45) | J46: =(F46+I46)/B46*100 | K46: =SUM(K2:K45)

Sheet Simplemarketplace_10000_0.01_no_pi
A1: Operator | B1: Total | C1: Equivalent | D1: Redundant | E1: Valid | F1: Killed | G1: Live | H1: Timedout | I1: Stillborn | J1: Mutation Score | K1: Testing Time
A2: ACM | B2: 0 | C2: 0 | D2: 0 | E2: 0 | F2: 0 | G2: 0 | H2: 0 | I2: 0 | K2: 0
A3: AOR | B3: 0 | C3: 0 | D3: 0 | E3: 0 | F3: 0 | G3: 0 | H3: 0 | I3: 0 | K3: 0
A4: AVR | B4: 0 | C4: 0 | D4: 0 | E4: 0 | F4: 0 | G4: 0 | H4: 0 | I4: 0 | K4: 0
A5: BCRD | B5: 0 | C5: 0 | D5: 0 | E5: 0 | F5: 0 | G5: 0 | H5: 0 | I5: 0 | K5: 0
A6: BLR | B6: 5 | C6: 0 | D6: 0 | E6: 5 | F6: 5 | G6: 0 | H6: 0 | I6: 0 | J6: 100 | K6: 1.05935
A7: BOR | B7: 10 | C7: 0 | D7: 0 | E7: 10 | F7: 10 | G7: 0 | H7: 0 | I7: 0 | J7: 100 | K7: 2.1236833
A8: CBD | B8: 0 | C8: 0 | D8: 0 | E8: 0 | F8: 0 | G8: 0 | H8: 0 | I8: 0 | K8: 0
A9: CCD | B9: 1 | C9: 0 | D9: 0 | E9: 1 | F9: 1 | G9: 0 | H9: 0 | I9: 0 | J9: 100 | K9: 0.20676667
A10: CSC | B10: 12 | C10: 0 | D10: 0 | E10: 12 | F10: 10 | G10: 2 | H10: 0 | I10: 0 | J10: 83.333333 | K10: 6.1061
A11: DLR | B11: 1 | C11: 0 | D11: 0 | E11: 0 | F11: 0 | G11: 0 | H11: 0 | I11: 1 | K11: 0
A12: DOD | B12: 0 | C12: 0 | D12: 0 | E12: 0 | F12: 0 | G12: 0 | H12: 0 | I12: 0 | K12: 0
A13: ECS | B13: 0 | C13: 0 | D13: 0 | E13: 0 | F13: 0 | G13: 0 | H13: 0 | I13: 0 | K13: 0
A14: EED | B14: 0 | C14: 0 | D14: 0 | E14: 0 | F14: 0 | G14: 0 | H14: 0 | I14: 0 | K14: 0
A15: EHC | B15: 8 | C15: 0 | D15: 0 | E15: 8 | F15: 3 | G15: 5 | H15: 0 | I15: 0 | J15: 37.5 | K15: 10.929167
A16: ER | B16: 9 | C16: 0 | D16: 0 | E16: 9 | F16: 6 | G16: 3 | H16: 0 | I16: 0 | J16: 66.666667 | K16: 7.4333
A17: ETR | B17: 0 | C17: 0 | D17: 0 | E17: 0 | F17: 0 | G17: 0 | H17: 0 | I17: 0 | K17: 0
A18: FVR | B18: 3 | C18: 0 | D18: 0 | E18: 3 | F18: 3 | G18: 0 | H18: 0 | I18: 0 | J18: 100 | K18: 0.6335
A19: GVR | B19: 0 | C19: 0 | D19: 0 | E19: 0 | F19: 0 | G19: 0 | H19: 0 | I19: 0 | K19: 0
A20: HLR | B20: 0 | C20: 0 | D20: 0 | E20: 0 | F20: 0 | G20: 0 | H20: 0 | I20: 0 | K20: 0
A21: ILR | B21: 4 | C21: 0 | D21: 0 | E21: 4 | F21: 3 | G21: 1 | H21: 0 | I21: 0 | J21: 75 | K21: 2.69935
A22: ICM | B22: 0 | C22: 0 | D22: 0 | E22: 0 | F22: 0 | G22: 0 | H22: 0 | I22: 0 | K22: 0
A23: LSC | B23: 0 | C23: 0 | D23: 0 | E23: 0 | F23: 0 | G23: 0 | H23: 0 | I23: 0 | K23: 0
A24: PKD | B24: 0 | C24: 0 | D24: 0 | E24: 0 | F24: 0 | G24: 0 | H24: 0 | I24: 0 | K24: 0
A25: MCR | B25: 0 | C25: 0 | D25: 0 | E25: 0 | F25: 0 | G25: 0 | H25: 0 | I25: 0 | K25: 0
A26: MOC | B26: 0 | C26: 0 | D26: 0 | E26: 0 | F26: 0 | G26: 0 | H26: 0 | I26: 0 | K26: 0
A27: MOD | B27: 0 | C27: 0 | D27: 0 | E27: 0 | F27: 0 | G27: 0 | H27: 0 | I27: 0 | K27: 0
A28: MOI | B28: 0 | C28: 0 | D28: 0 | E28: 0 | F28: 0 | G28: 0 | H28: 0 | I28: 0 | K28: 0
A29: MOR | B29: 0 | C29: 0 | D29: 0 | E29: 0 | F29: 0 | G29: 0 | H29: 0 | I29: 0 | K29: 0
A30: OLFD | B30: 0 | C30: 0 | D30: 0 | E30: 0 | F30: 0 | G30: 0 | H30: 0 | I30: 0 | K30: 0
A31: OMD | B31: 0 | C31: 0 | D31: 0 | E31: 0 | F31: 0 | G31: 0 | H31: 0 | I31: 0 | K31: 0
A32: ORFD | B32: 0 | C32: 0 | D32: 0 | E32: 0 | F32: 0 | G32: 0 | H32: 0 | I32: 0 | K32: 0
A33: RSD | B33: 0 | C33: 0 | D33: 0 | E33: 0 | F33: 0 | G33: 0 | H33: 0 | I33: 0 | K33: 0
... A44: VUR | B44: 0 | C44: 0 | D44: 0 | E44: 0 | F44: 0 | G44: 0 | H44: 0 | I44: 0 | K44: 0
A45: VVR | B45: 4 | C45: 0 | D45: 0 | E45: 4 | F45: 3 | G45: 1 | H45: 0 | I45: 0 | J45: 75 | K45: 2.6830833
A46: All | B46: =SUM(B2:B45) | C46: =SUM(C2:C45) | D46: =SUM(D2:D45) | E46: =SUM(E2:E45) | F46: =SUM(F2:F45) | G46: =SUM(G2:G45) | H46: =SUM(H2:H45) | I46: =SUM(I2:I45) | J46: =(F46+I46)/B46*100 | K46: =SUM(K2:K45)

Sheet ThermostatOperation_10000_0.5_no_pi
A1: Operator | B1: Total | C1: Equivalent | D1: Redundant | E1: Valid | F1: Killed | G1: Live | H1: Timedout | I1: Stillborn | J1: Mutation Score | K1: Testing Time
A2: ACM | B2: 0 | C2: 0 | D2: 0 | E2: 0 | F2: 0 | G2: 0 | H2: 0 | I2: 0 | K2: 0
A3: AOR | B3: 0 | C3: 0 | D3: 0 | E3: 0 | F3: 0 | G3: 0 | H3: 0 | I3: 0 | K3: 0
A4: AVR | B4: 0 | C4: 0 | D4: 0 | E4: 0 | F4: 0 | G4: 0 | H4: 0 | I4: 0 | K4: 0
A5: BCRD | B5: 0 | C5: 0 | D5: 0 | E5: 0 | F5: 0 | G5: 0 | H5: 0 | I5: 0 | K5: 0
A6: BLR | B6: 8 | C6: 0 | D6: 0 | E6: 8 | F6: 8 | G6: 0 | H6: 0 | I6: 0 | J6: 100 | K6: 1.65465
A7: BOR | B7: 12 | C7: 0 | D7: 0 | E7: 12 | F7: 11 | G7: 1 | H7: 0 | I7: 0 | J7: 91.666667 | K7: 4.9760167
A8: CBD | B8: 0 | C8: 0 | D8: 0 | E8: 0 | F8: 0 | G8: 0 | H8: 0 | I8: 0 | K8: 0
A9: CCD | B9: 1 | C9: 0 | D9: 0 | E9: 1 | F9: 1 | G9: 0 | H9: 0 | I9: 0 | J9: 100 | K9: 0.20613333
A10: CSC | B10: 12 | C10: 0 | D10: 0 | E10: 12 | F10: 10 | G10: 2 | H10: 0 | I10: 0 | J10: 83.333333 | K10: 8.1228833
A11: DLR | B11: 0 | C11: 0 | D11: 0 | E11: 0 | F11: 0 | G11: 0 | H11: 0 | I11: 0 | K11: 0
A12: DOD | B12: 0 | C12: 0 | D12: 0 | E12: 0 | F12: 0 | G12: 0 | H12: 0 | I12: 0 | K12: 0
A13: ECS | B13: 0 | C13: 0 | D13: 0 | E13: 0 | F13: 0 | G13: 0 | H13: 0 | I13: 0 | K13: 0
A14: EED | B14: 0 | C14: 0 | D14: 0 | E14: 0 | F14: 0 | G14: 0 | H14: 0 | I14: 0 | K14: 0
A15: EHC | B15: 12 | C15: 0 | D15: 0 | E15: 12 | F15: 3 | G15: 9 | H15: 0 | I15: 0 | J15: 25 | K15: 28.806483
A16: ER | B16: 9 | C16: 0 | D16: 0 | E16: 9 | F16: 7 | G16: 2 | H16: 0 | I16: 0 | J16: 77.777778 | K16: 7.5392667
A17: ETR | B17: 0 | C17: 0 | D17: 0 | E17: 0 | F17: 0 | G17: 0 | H17: 0 | I17: 0 | K17: 0
A18: FVR | B18: 3 | C18: 0 | D18: 0 | E18: 3 | F18: 3 | G18: 0 | H18: 0 | I18: 0 | J18: 100 | K18: 0.62276667
A19: GVR | B19: 0 | C19: 0 | D19: 0 | E19: 0 | F19: 0 | G19: 0 | H19: 0 | I19: 0 | K19: 0
A20: HLR | B20: 0 | C20: 0 | D20: 0 | E20: 0 | F20: 0 | G20: 0 | H20: 0 | I20: 0 | K20: 0
A21: ILR | B21: 9 | C21: 0 | D21: 0 | E21: 9 | F21: 9 | G21: 0 | H21: 0 | I21: 0 | J21: 100 | K21: 1.8731167
A22: ICM | B22: 0 | C22: 0 | D22: 0 | E22: 0 | F22: 0 | G22: 0 | H22: 0 | I22: 0 | K22: 0
A23: LSC | B23: 0 | C23: 0 | D23: 0 | E23: 0 | F23: 0 | G23: 0 | H23: 0 | I23: 0 | K23: 0
A24: PKD | B24: 0 | C24: 0 | D24: 0 | E24: 0 | F24: 0 | G24: 0 | H24: 0 | I24: 0 | K24: 0
A25: MCR | B25: 0 | C25: 0 | D25: 0 | E25: 0 | F25: 0 | G25: 0 | H25: 0 | I25: 0 | K25: 0
A26: MOC | B26: 0 | C26: 0 | D26: 0 | E26: 0 | F26: 0 | G26: 0 | H26: 0 | I26: 0 | K26: 0
A27: MOD | B27: 0 | C27: 0 | D27: 0 | E27: 0 | F27: 0 | G27: 0 | H27: 0 | I27: 0 | K27: 0
A28: MOI | B28: 0 | C28: 0 | D28: 0 | E28: 0 | F28: 0 | G28: 0 | H28: 0 | I28: 0 | K28: 0
A29: MOR | B29: 0 | C29: 0 | D29: 0 | E29: 0 | F29: 0 | G29: 0 | H29: 0 | I29: 0 | K29: 0
A30: OLFD | B30: 0 | C30: 0 | D30: 0 | E30: 0 | F30: 0 | G30: 0 | H30: 0 | I30: 0 | K30: 0
A31: OMD | B31: 0 | C31: 0 | D31: 0 | E31: 0 | F31: 0 | G31: 0 | H31: 0 | I31: 0 | K31: 0
A32: ORFD | B32: 0 | C32: 0 | D32: 0 | E32: 0 | F32: 0 | G32: 0 | H32: 0 | I32: 0 | K32: 0
A33: RSD | B33: 0 | C33: 0 | D33: 0 | E33: 0 | F33: 0 | G33: 0 | H33: 0 | I33: 0 | K33: 0
... A44: VUR | B44: 0 | C44: 0 | D44: 0 | E44: 0 | F44: 0 | G44: 0 | H44: 0 | I44: 0 | K44: 0
A45: VVR | B45: 3 | C45: 0 | D45: 0 | E45: 3 | F45: 2 | G45: 1 | H45: 0 | I45: 0 | J45: 66.666667 | K45: 3.3694667
A46: All | B46: =SUM(B2:B45) | C46: =SUM(C2:C45) | D46: =SUM(D2:D45) | E46: =SUM(E2:E45) | F46: =SUM(F2:F45) | G46: =SUM(G2:G45) | H46: =SUM(H2:H45) | I46: =SUM(I2:I45) | J46: =(F46+I46)/B46*100 | K46: =SUM(K2:K45)

Sheet Token1_10000_0.01_no_pi
A1: Operator | B1: Total | C1: Equivalent | D1: Redundant | E1: Valid | F1: Killed | G1: Live | H1: Timedout | I1: Stillborn | J1: Mutation Score | K1: Testing Time
A2: ACM | B2: 0 | C2: 0 | D2: 0 | E2: 0 | F2: 0 | G2: 0 | H2: 0 | I2: 0 | K2: 0
A3: AOR | B3: 0 | C3: 0 | D3: 0 | E3: 0 | F3: 0 | G3: 0 | H3: 0 | I3: 0 | K3: 0
A4: AVR | B4: 0 | C4: 0 | D4: 0 | E4: 0 | F4: 0 | G4: 0 | H4: 0 | I4: 0 | K4: 0
A5: BCRD | B5: 0 | C5: 0 | D5: 0 | E5: 0 | F5: 0 | G5: 0 | H5: 0 | I5: 0 | K5: 0
A6: BLR | B6: 3 | C6: 0 | D6: 0 | E6: 3 | F6: 3 | G6: 0 | H6: 0 | I6: 0 | J6: 100 | K6: 0.69623333
A7: BOR | B7: 31 | C7: 0 | D7: 0 | E7: 31 | F7: 29 | G7: 2 | H7: 0 | I7: 0 | J7: 93.548387 | K7: 21.168167
A8: CBD | B8: 0 | C8: 0 | D8: 0 | E8: 0 | F8: 0 | G8: 0 | H8: 0 | I8: 0 | K8: 0
A9: CCD | B9: 1 | C9: 0 | D9: 0 | E9: 1 | F9: 1 | G9: 0 | H9: 0 | I9: 0 | J9: 100 | K9: 0.22043333
A10: CSC | B10: 18 | C10: 0 | D10: 0 | E10: 18 | F10: 13 | G10: 5 | H10: 0 | I10: 0 | J10: 72.222222 | K10: 39.78115
A11: DLR | B11: 2 | C11: 0 | D11: 0 | E11: 0 | F11: 0 | G11: 0 | H11: 0 | I11: 2 | K11: 0
A12: DOD | B12: 0 | C12: 0 | D12: 0 | E12: 0 | F12: 0 | G12: 0 | H12: 0 | I12: 0 | K12: 0
A13: ECS | B13: 0 | C13: 0 | D13: 0 | E13: 0 | F13: 0 | G13: 0 | H13: 0 | I13: 0 | K13: 0
A14: EED | B14: 0 | C14: 0 | D14: 0 | E14: 0 | F14: 0 | G14: 0 | H14: 0 | I14: 0 | K14: 0
A15: EHC | B15: 8 | C15: 0 | D15: 0 | E15: 8 | F15: 4 | G15: 4 | H15: 0 | I15: 0 | J15: 50 | K15: 28.85295
A16: ER | B16: 1 | C16: 0 | D16: 0 | E16: 1 | F16: 0 | G16: 1 | H16: 0 | I16: 0 | J16: 0 | K16: 6.7341833
A17: ETR | B17: 0 | C17: 0 | D17: 0 | E17: 0 | F17: 0 | G17: 0 | H17: 0 | I17: 0 | K17: 0
A18: FVR | B18: 5 | C18: 0 | D18: 0 | E18: 5 | F18: 5 | G18: 0 | H18: 0 | I18: 0 | J18: 100 | K18: 1.0731833
A19: GVR | B19: 0 | C19: 0 | D19: 0 | E19: 0 | F19: 0 | G19: 0 | H19: 0 | I19: 0 | K19: 0
A20: HLR | B20: 0 | C20: 0 | D20: 0 | E20: 0 | F20: 0 | G20: 0 | H20: 0 | I20: 0 | K20: 0
A21: ILR | B21: 3 | C21: 0 | D21: 0 | E21: 3 | F21: 3 | G21: 0 | H21: 0 | I21: 0 | J21: 100 | K21: 0.65108333
A22: ICM | B22: 0 | C22: 0 | D22: 0 | E22: 0 | F22: 0 | G22: 0 | H22: 0 | I22: 0 | K22: 0
A23: LSC | B23: 0 | C23: 0 | D23: 0 | E23: 0 | F23: 0 | G23: 0 | H23: 0 | I23: 0 | K23: 0
A24: PKD | B24: 0 | C24: 0 | D24: 0 | E24: 0 | F24: 0 | G24: 0 | H24: 0 | I24: 0 | K24: 0
A25: MCR | B25: 0 | C25: 0 | D25: 0 | E25: 0 | F25: 0 | G25: 0 | H25: 0 | I25: 0 | K25: 0
A26: MOC | B26: 0 | C26: 0 | D26: 0 | E26: 0 | F26: 0 | G26: 0 | H26: 0 | I26: 0 | K26: 0
A27: MOD | B27: 0 | C27: 0 | D27: 0 | E27: 0 | F27: 0 | G27: 0 | H27: 0 | I27: 0 | K27: 0
A28: MOI | B28: 0 | C28: 0 | D28: 0 | E28: 0 | F28: 0 | G28: 0 | H28: 0 | I28: 0 | K28: 0
A29: MOR | B29: 0 | C29: 0 | D29: 0 | E29: 0 | F29: 0 | G29: 0 | H29: 0 | I29: 0 | K29: 0
A30: OLFD | B30: 0 | C30: 0 | D30: 0 | E30: 0 | F30: 0 | G30: 0 | H30: 0 | I30: 0 | K30: 0
A31: OMD | B31: 0 | C31: 0 | D31: 0 | E31: 0 | F31: 0 | G31: 0 | H31: 0 | I31: 0 | K31: 0
A32: ORFD | B32: 0 | C32: 0 | D32: 0 | E32: 0 | F32: 0 | G32: 0 | H32: 0 | I32: 0 | K32: 0
A33: RSD | B33: 0 | C33: 0 | D33: 0 | E33: 0 | F33: 0 | G33: 0 | H33: 0 | I33: 0 | K33: 0
... A44: VUR | B44: 0 | C44: 0 | D44: 0 | E44: 0 | F44: 0 | G44: 0 | H44: 0 | I44: 0 | K44: 0
A45: VVR | B45: 5 | C45: 0 | D45: 0 | E45: 5 | F45: 1 | G45: 4 | H45: 0 | I45: 0 | J45: 20 | K45: 26.9678
A46: All | B46: =SUM(B2:B45) | C46: =SUM(C2:C45) | D46: =SUM(D2:D45) | E46: =SUM(E2:E45) | F46: =SUM(F2:F45) | G46: =SUM(G2:G45) | H46: =SUM(H2:H45) | I46: =SUM(I2:I45) | J46: =(F46+I46)/B46*100 | K46: =SUM(K2:K45)

Sheet WalletContract_10000_0.01_no_pi
A1: Operator | B1: Total | C1: Equivalent | D1: Redundant | E1: Valid | F1: Killed | G1: Live | H1: Timedout | I1: Stillborn | J1: Mutation Score | K1: Testing Time
A2: ACM | B2: 0 | C2: 0 | D2: 0 | E2: 0 | F2: 0 | G2: 0 | H2: 0 | I2: 0 | K2: 0
A3: AOR | B3: 0 | C3: 0 | D3: 0 | E3: 0 | F3: 0 | G3: 0 | H3: 0 | I3: 0 | K3: 0
A4: AVR | B4: 0 | C4: 0 | D4: 0 | E4: 0 | F4: 0 | G4: 0 | H4: 0 | I4: 0 | K4: 0
A5: BCRD | B5: 0 | C5: 0 | D5: 0 | E5: 0 | F5: 0 | G5: 0 | H5: 0 | I5: 0 | K5: 0
A6: BLR | B6: 3 | C6: 0 | D6: 0 | E6: 3 | F6: 3 | G6: 0 | H6: 0 | I6: 0 | J6: 100 | K6: 0.6104
A7: BOR | B7: 17 | C7: 0 | D7: 0 | E7: 17 | F7: 17 | G7: 0 | H7: 0 | I7: 0 | J7: 100 | K7: 3.5332667
A8: CBD | B8: 0 | C8: 0 | D8: 0 | E8: 0 | F8: 0 | G8: 0 | H8: 0 | I8: 0 | K8: 0
A9: CCD | B9: 1 | C9: 0 | D9: 0 | E9: 1 | F9: 1 | G9: 0 | H9: 0 | I9: 0 | J9: 100 | K9: 0.20551667
A10: CSC | B10: 12 | C10: 0 | D10: 0 | E10: 12 | F10: 10 | G10: 2 | H10: 0 | I10: 0 | J10: 83.333333 | K10: 4.9512667
A11: DLR | B11: 0 | C11: 0 | D11: 0 | E11: 0 | F11: 0 | G11: 0 | H11: 0 | I11: 0 | K11: 0
A12: DOD | B12: 0 | C12: 0 | D12: 0 | E12: 0 | F12: 0 | G12: 0 | H12: 0 | I12: 0 | K12: 0
A13: ECS | B13: 0 | C13: 0 | D13: 0 | E13: 0 | F13: 0 | G13: 0 | H13: 0 | I13: 0 | K13: 0
A14: EED | B14: 0 | C14: 0 | D14: 0 | E14: 0 | F14: 0 | G14: 0 | H14: 0 | I14: 0 | K14: 0
A15: EHC | B15: 6 | C15: 0 | D15: 0 | E15: 6 | F15: 3 | G15: 3 | H15: 0 | I15: 0 | J15: 50 | K15: 4.9533333
A16: ER | B16: 8 | C16: 0 | D16: 0 | E16: 8 | F16: 6 | G16: 2 | H16: 0 | I16: 0 | J16: 75 | K16: 4.0854167
A17: ETR | B17: 0 | C17: 0 | D17: 0 | E17: 0 | F17: 0 | G17: 0 | H17: 0 | I17: 0 | K17: 0
A18: FVR | B18: 3 | C18: 0 | D18: 0 | E18: 3 | F18: 3 | G18: 0 | H18: 0 | I18: 0 | J18: 100 | K18: 0.61348333
A19: GVR | B19: 0 | C19: 0 | D19: 0 | E19: 0 | F19: 0 | G19: 0 | H19: 0 | I19: 0 | K19: 0
A20: HLR | B20: 0 | C20: 0 | D20: 0 | E20: 0 | F20: 0 | G20: 0 | H20: 0 | I20: 0 | K20: 0
A21: ILR | B21: 7 | C21: 0 | D21: 0 | E21: 7 | F21: 7 | G21: 0 | H21: 0 | I21: 0 | J21: 100 | K21: 1.42695
A22: ICM | B22: 0 | C22: 0 | D22: 0 | E22: 0 | F22: 0 | G22: 0 | H22: 0 | I22: 0 | K22: 0
A23: LSC | B23: 0 | C23: 0 | D23: 0 | E23: 0 | F23: 0 | G23: 0 | H23: 0 | I23: 0 | K23: 0
A24: PKD | B24: 0 | C24: 0 | D24: 0 | E24: 0 | F24: 0 | G24: 0 | H24: 0 | I24: 0 | K24: 0
A25: MCR | B25: 0 | C25: 0 | D25: 0 | E25: 0 | F25: 0 | G25: 0 | H25: 0 | I25: 0 | K25: 0
A26: MOC | B26: 0 | C26: 0 | D26: 0 | E26: 0 | F26: 0 | G26: 0 | H26: 0 | I26: 0 | K26: 0
A27: MOD | B27: 0 | C27: 0 | D27: 0 | E27: 0 | F27: 0 | G27: 0 | H27: 0 | I27: 0 | K27: 0
A28: MOI | B28: 0 | C28: 0 | D28: 0 | E28: 0 | F28: 0 | G28: 0 | H28: 0 | I28: 0 | K28: 0
A29: MOR | B29: 0 | C29: 0 | D29: 0 | E29: 0 | F29: 0 | G29: 0 | H29: 0 | I29: 0 | K29: 0
A30: OLFD | B30: 0 | C30: 0 | D30: 0 | E30: 0 | F30: 0 | G30: 0 | H30: 0 | I30: 0 | K30: 0
A31: OMD | B31: 0 | C31: 0 | D31: 0 | E31: 0 | F31: 0 | G31: 0 | H31: 0 | I31: 0 | K31: 0
A32: ORFD | B32: 0 | C32: 0 | D32: 0 | E32: 0 | F32: 0 | G32: 0 | H32: 0 | I32: 0 | K32: 0
A33: RSD | B33: 0 | C33: 0 | D33: 0 | E33: 0 | F33: 0 | G33: 0 | H33: 0 | I33: 0 | K33: 0
... A44: VUR | B44: 0 | C44: 0 | D44: 0 | E44: 0 | F44: 0 | G44: 0 | H44: 0 | I44: 0 | K44: 0
A45: VVR | B45: 2 | C45: 0 | D45: 0 | E45: 2 | F45: 1 | G45: 1 | H45: 0 | I45: 0 | J45: 50 | K45: 1.62285
A46: All | B46: =SUM(B2:B45) | C46: =SUM(C2:C45) | D46: =SUM(D2:D45) | E46: =SUM(E2:E45) | F46: =SUM(F2:F45) | G46: =SUM(G2:G45) | H46: =SUM(H2:H45) | I46: =SUM(I2:I45) | J46: =(F46+I46)/B46*100 | K46: =SUM(K2:K45)
